Workbook
Name Cat_Computer: CODEX!$AL$2:$AL$17
Name Cat_Display: CODEX!$AM$2:$AM$17
Name Cat_IOT: CODEX!$AQ$2:$AQ$5
Name Cat_Network_Device: CODEX!$AN$2:$AN$17
Name Cat_Peripheral: CODEX!$AO$2:$AO$21
Name Cat_Server: CODEX!$AR$2:$AR$3
Name Cat_Utilities: CODEX!$AP$2:$AP$15
Name Category_List: CODEX!$AK$2:$AK$15
Name COMPUTER: IOT!$B$1
Name COMPUTER: SERVER!$B$1
Name COMPUTER: COMPUTER!$B$1
Name Owner_list: CODEX!$AI$1:$AI$6

Sheet Dashboard
B1: DASHBOARD ASET PERANGKAT IT PGT
B2: Ringkasan inventaris aktif • data terhubung langsung ke seluruh register aset
B4: COMPUTER | E4: DISPLAY | H4: NETWORK DEVICE | K4: PERIPHERAL | N4: UTILITIES
B5: ='BASE-DATA'!$C8 -> 57 | E5: ='BASE-DATA'!$C9 -> 22 | H5: ='BASE-DATA'!$C10 -> 8 | K5: ='BASE-DATA'!$C11 -> 57 | N5: ='BASE-DATA'!$C12 -> 6
B8: TOTAL ASSET | F8: DEVICES HANDOVER | J8: IDLE STATUS | N8: SHARED STATUS
B9: =SUM('BASE-DATA'!C8:C12) -> 150 | F9: =SUM(HANDOVER!$R$2:$R$1048576) -> 47 | J9: =SUM('BASE-DATA'!D8:D12) -> 27 | N9: =SUM('BASE-DATA'!E8:F12) -> 116
F13: NOTE: This New Handover
B16: ASSET CATEGORIES

Sheet COMPUTER
A1: 1 | B1: Sample : TTBBKSK000 | C1: Asset Order | E1: Asset ( Category 1 - Computer ) | O1: Operating System | R1: IP Address | T1: MAC Address | V1: Processor | Y1: Ram | AE1: Video (GPU) | AG1: Storage | AJ1: Display | AR1: Image Device
A2: No | B2: No Asset | C2: Purchase Date | D2: No PO | E2: Location | F2: Current Location | G2: Categories | H2: Sub-Cat | I2: Device Name | J2: Short Name | K2: S/N PC UNIT | L2: Manufacture | M2: Model Name | N2: Type | O2: Hostname | P2: Version | Q2: Product Key | R2: IP_WIFI | S2: IP_ETH | T2: MC_WIFI | U2: MC_ETH | V2: Processor_MFG | W2: Model | X2: Specifik | Y2: RAM_MFG | Z2: RAM_Type | AA2: Speed | AB2: Slot | AC2: Chanel | AD2: Size (GB) | AE2: GPU_Model | AF2: Onboard (Y/N) | AG2: Storage_MFG | AH2: Storage_Type | AI2: Storage_Size (GB) | AJ2: Model11 | AK2: Type12 | AL2: Size | AM2: Device Condition | AN2: Ownership | AO2: Asset PIC | AP2: Usage Status | AQ2: NOTES | AR2: img_1 | AS2: img_2 | AT2: img_3 | AU2: Labeling | AV2: Handover Doc
A3: =IF(tbl_computer[[#This Row],[No Asset]]<>"",SUBTOTAL(3,INDEX(tbl_computer[No Asset],1):tbl_computer[[#This Row],[No Asset]]),"") -> 0 | B3: =IF(OR(tbl_computer[[#This Row],[Purchase Date]]="",tbl_computer[[#This Row],[Categories]]=""),"", TEXT(tbl_computer[[#This Row],[Purchase Date]],"YYMM")& _xlfn.XLOOKUP(tbl_computer[[#This Row],[Categories]],CODEX!$Z:$Z,CODEX!$W:$W,"")& TEXT(_xlfn.XLOOKUP(tbl_computer[[#This Row],[Categories]],CODEX!$Z:$Z,CODEX!$Y:$Y,""),"00")& TEXT(COUNTIFS(INDEX(tbl_computer[Purchase Date],1):tbl_computer[[#This Row],[Purchase Date]],">="&DATE(YEAR(tbl_computer[[#This Row],[Purchase Date]]),MONTH(tbl_computer[[#This Row],[Purchase Date]]),1),INDEX(tbl_computer[Purchase Date],1):tbl_computer[[#This Row],[Purchase Date]],"<"&EDATE(DATE(YEAR(tbl_computer[[#This Row],[Purchase Date]]),MONTH(tbl_computer[[#This Row],[Purchase Date]]),1),1),INDEX(tbl_computer[Categories],1):tbl_computer[[#This Row],[Categories]],tbl_computer[[#This Row],[Categories]]),"000")) -> 2601101001 | C3: 46023 | D3: PO-001 | E3: Patimban | F3: Customs Building | G3: Computer | H3: PC | I3: HP Pro Mini 400G9 Desktop PC | J3: MFF PC | K3: 8CC6090X4D | L3: HP | M3: Pro Mini 400G9 | N3: 400G9 | O3: PBPCIT-CUSTOMS | P3: W 11 Pro | Q3: 00355-63810-25299-AAOEM | S3: N/A | T3: EC-3A-56-78-25-C8 | U3: B4-E2-5B-77-5C-B5 | V3: INTEL | W3: Core i7 14700T | X3: Core(TM) i7-14700T (1.30 GHz) | Y3: Samsung | Z3: DDR5 | AA3: 5600 | AB3: 2 | AC3: Dual Chanel | AD3: 16 | AE3: UHD Graphics 770 | AF3: Y | AG3: KIOXIA | AH3: SSD-NVME | AI3: 1024 | AJ3: 4K UHD (3.840 x 2.160 piksel) | AK3: UA55DU8000 | AL3: 55" | AM3: Good | AN3: PGT | AO3: IT | AP3: Shared | AQ3: EX. Jetty; For CCTV monitoring | AU3: TRUE | AV3: =_xlfn.IFNA(INDEX(tbl_handover[No. Handover],MATCH(tbl_computer[[#This Row],[No Asset]],tbl_handover[Asset Code],0)),"") -> SR.26.09.0001/IX/2026/PGT/IT/INT
A4: =IF(tbl_computer[[#This Row],[No Asset]]<>"",SUBTOTAL(3,INDEX(tbl_computer[No Asset],1):tbl_computer[[#This Row],[No Asset]]),"") -> 0 | B4: =IF(OR(tbl_computer[[#This Row],[Purchase Date]]="",tbl_computer[[#This Row],[Categories]]=""),"", TEXT(tbl_computer[[#This Row],[Purchase Date]],"YYMM")& _xlfn.XLOOKUP(tbl_computer[[#This Row],[Categories]],CODEX!$Z:$Z,CODEX!$W:$W,"")& TEXT(_xlfn.XLOOKUP(tbl_computer[[#This Row],[Categories]],CODEX!$Z:$Z,CODEX!$Y:$Y,""),"00")& TEXT(COUNTIFS(INDEX(tbl_computer[Purchase Date],1):tbl_computer[[#This Row],[Purchase Date]],">="&DATE(YEAR(tbl_computer[[#This Row],[Purchase Date]]),MONTH(tbl_computer[[#This Row],[Purchase Date]]),1),INDEX(tbl_computer[Purchase Date],1):tbl_computer[[#This Row],[Purchase Date]],"<"&EDATE(DATE(YEAR(tbl_computer[[#This Row],[Purchase Date]]),MONTH(tbl_computer[[#This Row],[Purchase Date]]),1),1),INDEX(tbl_computer[Categories],1):tbl_computer[[#This Row],[Categories]],tbl_computer[[#This Row],[Categories]]),"000")) -> 2609101001 | C4: 46268 | D4: PO-002 | E4: Patimban | F4: KSOP Building | G4: Computer | H4: PC | I4: HP ProDesk 4 Mini G1i Desktop AI PC | J4: MFF PC | K4: 8CC6062FV7 | L4: HP | M4: ProDesk 4 Mini G1i | N4: G1i | O4: PBPCIT-KSOP | P4: W 11 Pro | Q4: XMNWX-R3HVM-CGKD7-R3W7X-H6DGR | S4: N/A | V4: INTEL | W4: Ultra 5 225T | X4: Intel(R) Core(TM) Ultra 5 225T (2.50 GHz) | Y4: Samsung | Z4: DDR5 | AA4: 5600 | AB4: 2 | AC4: Dual Chanel | AD4: 16 | AE4: Intel ARC Graphics | AF4: Y | AG4: SAMSUNG | AH4: SSD-NVME | AI4: 512 | AJ4: 4K UHD (3.840 x 2.160 piksel) | AK4: UA50U8000 | AL4: 50" | AM4: New | AN4: PGT | AO4: IT | AP4: Shared | AQ4: For CCTV monitoring | AU4: TRUE | AV4: =_xlfn.IFNA(INDEX(tbl_handover[No. Handover],MATCH(tbl_computer[[#This Row],[No Asset]],tbl_handover[Asset Code],0)),"") -> SR.26.09.0002/IX/2026/PGT/IT/INT
A5: =IF(tbl_computer[[#This Row],[No Asset]]<>"",SUBTOTAL(3,INDEX(tbl_computer[No Asset],1):tbl_computer[[#This Row],[No Asset]]),"") -> 0 | B5: =IF(OR(tbl_computer[[#This Row],[Purchase Date]]="",tbl_computer[[#This Row],[Categories]]=""),"", TEXT(tbl_computer[[#This Row],[Purchase Date]],"YYMM")& _xlfn.XLOOKUP(tbl_computer[[#This Row],[Categories]],CODEX!$Z:$Z,CODEX!$W:$W,"")& TEXT(_xlfn.XLOOKUP(tbl_computer[[#This Row],[Categories]],CODEX!$Z:$Z,CODEX!$Y:$Y,""),"00")& TEXT(COUNTIFS(INDEX(tbl_computer[Purchase Date],1):tbl_computer[[#This Row],[Purchase Date]],">="&DATE(YEAR(tbl_computer[[#This Row],[Purchase Date]]),MONTH(tbl_computer[[#This Row],[Purchase Date]]),1),INDEX(tbl_computer[Purchase Date],1):tbl_computer[[#This Row],[Purchase Date]],"<"&EDATE(DATE(YEAR(tbl_computer[[#This Row],[Purchase Date]]),MONTH(tbl_computer[[#This Row],[Purchase Date]]),1),1),INDEX(tbl_computer[Categories],1):tbl_computer[[#This Row],[Categories]],tbl_computer[[#This Row],[Categories]]),"000")) -> 2609101002 | C5: 46268 | D5: PO-002 | E5: Patimban | F5: Engineer Room | G5: Computer | H5: Notebook | I5: HP ZBook 8 G1i 14 inch Mobile Workstation PC | J5: NOTEBOOK | K5: 5CG60633X1 | L5: HP | M5: ZBook 8 G1i | N5: ZBook 8 G1i | O5: JKNBIS-QUENTIN | P5: W 11 Pro | Q5: QN6VY-VY3DF-PGFT6-BDPWT-QYJGG | R5: 10.90.10.87 | S5: N/A | T5: AC-F4-66-CF-BA-C2 | U5: 9C-97-1B-FF-6C-7A | V5: INTEL | W5: Ultra 7 265H | X5: Intel(R) Core(TM) Ultra 7 265H (16 CPUs), ~2.2GHz | Y5: Samsung | Z5: DDR5 | AA5: 5600 | AB5: 2 | AC5: Singgle Chanel | AD5: 32 | AE5: NVDIA RTX500 4 GB GDDR6 Dedicated | AF5: Y | AG5: PC SN5000S | AH5: SSD-NVME | AI5: 1024 | AJ5: WQXGA(2560x1600) Anti-Glare | AK5: WQXGA | AL5: 14" | AM5: New | AN5: PGT | AO5: IT | AP5: Idle | AQ5: For Manager Engineer (Quentin Bonny); include notebook bag | AU5: TRUE | AV5: =_xlfn.IFNA(INDEX(tbl_handover[No. Handover],MATCH(tbl_computer[[#This Row],[No Asset]],tbl_handover[Asset Code],0)),"") -> SR.26.09.0009/IX/2026/PGT/IT/INT
A6: =IF(tbl_computer[[#This Row],[No Asset]]<>"",SUBTOTAL(3,INDEX(tbl_computer[No Asset],1):tbl_computer[[#This Row],[No Asset]]),"") -> 0 | B6: =IF(OR(tbl_computer[[#This Row],[Purchase Date]]="",tbl_computer[[#This Row],[Categories]]=""),"", TEXT(tbl_computer[[#This Row],[Purchase Date]],"YYMM")& _xlfn.XLOOKUP(tbl_computer[[#This Row],[Categories]],CODEX!$Z:$Z,CODEX!$W:$W,"")& TEXT(_xlfn.XLOOKUP(tbl_computer[[#This Row],[Categories]],CODEX!$Z:$Z,CODEX!$Y:$Y,""),"00")& TEXT(COUNTIFS(INDEX(tbl_computer[Purchase Date],1):tbl_computer[[#This Row],[Purchase Date]],">="&DATE(YEAR(tbl_computer[[#This Row],[Purchase Date]]),MONTH(tbl_computer[[#This Row],[Purchase Date]]),1),INDEX(tbl_computer[Purchase Date],1):tbl_computer[[#This Row],[Purchase Date]],"<"&EDATE(DATE(YEAR(tbl_computer[[#This Row],[Purchase Date]]),MONTH(tbl_computer[[#This Row],[Purchase Date]]),1),1),INDEX(tbl_computer[Categories],1):tbl_computer[[#This Row],[Categories]],tbl_computer[[#This Row],[Categories]]),"000")) -> 2609101003 | C6: 46268 | D6: PO-002 | E6: Patimban | F6: Engineer Room | G6: Computer | H6: PC | I6: HP ProDesk 4 Mini G1i Desktop AI PC | J6: MFF PC | K6: 8CC6062FT4 | L6: HP | M6: ProDesk 4 Mini G1i | O6: PBPCOP-LABOUR2 | P6: W 11 Pro | Q6: NPDHG-MFP9V-RPD42-276F6-GMVCM | R6: 10.90.10.114 | S6: N/A | T6: 44-25-38-33-F0-A1 | U6: B4-E2-5B-72-44-CA | V6: INTEL | W6: Ultra 5 225T | X6: Intel(R) Core(TM) Ultra 5 225T (2.50 GHz) | Y6: Samsung | Z6: DDR5 | AA6: 5600 | AB6: 2 | AC6: Dual Chanel | AD6: 16 | AE6: Intel ARC Graphics | AF6: Y | AG6: SAMSUNG | AH6: SSD-NVME | AI6: 512 | AJ6: IPS Full HD (1920×1080) – 120 Hz | AK6: F27F320GA | AL6: 27" | AM6: New | AN6: PGT | AO6: IT | AP6: In used by User | AQ6: Exchange from PBPCIT-ITSTAFF; Asset allocation for Labour Staff | AU6: TRUE | AV6: =_xlfn.IFNA(INDEX(tbl_handover[No. Handover],MATCH(tbl_computer[[#This Row],[No Asset]],tbl_handover[Asset Code],0)),"") -> SR.26.09.0005/IX/2026/PGT/IT/INT
A7: =IF(tbl_computer[[#This Row],[No Asset]]<>"",SUBTOTAL(3,INDEX(tbl_computer[No Asset],1):tbl_computer[[#This Row],[No Asset]]),"") -> 0 | B7: =IF(OR(tbl_computer[[#This Row],[Purchase Date]]="",tbl_computer[[#This Row],[Categories]]=""),"", TEXT(tbl_computer[[#This Row],[Purchase Date]],"YYMM")& _xlfn.XLOOKUP(tbl_computer[[#This Row],[Categories]],CODEX!$Z:$Z,CODEX!$W:$W,"")& TEXT(_xlfn.XLOOKUP(tbl_computer[[#This Row],[Categories]],CODEX!$Z:$Z,CODEX!$Y:$Y,""),"00")& TEXT(COUNTIFS(INDEX(tbl_computer[Purchase Date],1):tbl_computer[[#This Row],[Purchase Date]],">="&DATE(YEAR(tbl_computer[[#This Row],[Purchase Date]]),MONTH(tbl_computer[[#This Row],[Purchase Date]]),1),INDEX(tbl_computer[Purchase Date],1):tbl_computer[[#This Row],[Purchase Date]],"<"&EDATE(DATE(YEAR(tbl_computer[[#This Row],[Purchase Date]]),MONTH(tbl_computer[[#This Row],[Purchase Date]]),1),1),INDEX(tbl_computer[Categories],1):tbl_computer[[#This Row],[Categories]],tbl_computer[[#This Row],[Categories]]),"000")) -> 2609101004 | C7: 46268 | D7: PO-002 | E7: Patimban | F7: Engineer Room | G7: Computer | H7: PC | I7: HP ProDesk 4 Mini G1i Desktop AI PC | J7: MFF PC | K7: 8CC6062FR8 | L7: HP | M7: ProDesk 4 Mini G1i | O7: PBPCIT-ASSET260801 | P7: W 11 Pro | Q7: 2NQVP-9T3PW-6KXQJ-FP2J2-GQ78Y | R7: 10.90.10.93 | S7: N/A | T7: 44-25-38-33-EF-53 | U7: B4-E2-5B-72-45-F9 | V7: INTEL | W7: Ultra 5 225T | X7: Intel(R) Core(TM) Ultra 5 225T (2.50 GHz) | Y7: Samsung | Z7: DDR5 | AA7: 5600 | AB7: 2 | AC7: Dual Chanel | AD7: 16 | AE7: Intel ARC Graphics | AF7: Y | AG7: SAMSUNG | AH7: SSD-NVME | AI7: 512 | AJ7: IPS Full HD (1920×1080) – 120 Hz | AK7: F27F320GA | AL7: 27" | AM7: New | AN7: PGT | AO7: IT | AP7: Idle | AQ7: Spare PC desktop | AU7: TRUE | AV7: =_xlfn.IFNA(INDEX(tbl_handover[No. Handover],MATCH(tbl_computer[[#This Row],[No Asset]],tbl_handover[Asset Code],0)),"")
A8: =IF(tbl_computer[[#This Row],[No Asset]]<>"",SUBTOTAL(3,INDEX(tbl_computer[No Asset],1):tbl_computer[[#This Row],[No Asset]]),"") -> 0 | B8: =IF(OR(tbl_computer[[#This Row],[Purchase Date]]="",tbl_computer[[#This Row],[Categories]]=""),"", TEXT(tbl_computer[[#This Row],[Purchase Date]],"YYMM")& _xlfn.XLOOKUP(tbl_computer[[#This Row],[Categories]],CODEX!$Z:$Z,CODEX!$W:$W,"")& TEXT(_xlfn.XLOOKUP(tbl_computer[[#This Row],[Categories]],CODEX!$Z:$Z,CODEX!$Y:$Y,""),"00")& TEXT(COUNTIFS(INDEX(tbl_computer[Purchase Date],1):tbl_computer[[#This Row],[Purchase Date]],">="&DATE(YEAR(tbl_computer[[#This Row],[Purchase Date]]),MONTH(tbl_computer[[#This Row],[Purchase Date]]),1),INDEX(tbl_computer[Purchase Date],1):tbl_computer[[#This Row],[Purchase Date]],"<"&EDATE(DATE(YEAR(tbl_computer[[#This Row],[Purchase Date]]),MONTH(tbl_computer[[#This Row],[Purchase Date]]),1),1),INDEX(tbl_computer[Categories],1):tbl_computer[[#This Row],[Categories]],tbl_computer[[#This Row],[Categories]]),"000")) -> 2609101005 | C8: 46268 | D8: PO-002 | E8: Patimban | F8: Engineer Room | G8: Computer | H8: PC | I8: HP ProDesk 4 Mini G1i Desktop AI PC | J8: MFF PC | K8: 8CC6062FS5 | L8: HP | M8: ProDesk 4 Mini G1i | O8: PBPCEQ-STAFF2 | P8: W 11 Pro | Q8: MX22P-KNGKJ-CTYT3-WB4Q4-844JY | R8: 10.90.10.94 | S8: N/A | T8: 44-25-38-33-74-13 | U8: B4-E2-5B-72-45-74 | V8: INTEL | W8: Ultra 5 225T | X8: Intel(R) Core(TM) Ultra 5 225T (2.50 GHz) | Y8: Samsung | Z8: DDR5 | AA8: 5600 | AB8: 2 | AC8: Dual Chanel | AD8: 16 | AE8: Intel ARC Graphics | AF8: Y | AG8: SAMSUNG | AH8: SSD-NVME | AI8: 512 | AJ8: IPS Full HD (1920×1080) – 120 Hz | AK8: F27F320GA | AL8: 27" | AM8: New | AN8: PGT | AO8: IT | AP8: Idle | AQ8: Asset allocation for Equipment Staff 2 | AU8: FALSE | AV8: =_xlfn.IFNA(INDEX(tbl_handover[No. Handover],MATCH(tbl_computer[[#This Row],[No Asset]],tbl_handover[Asset Code],0)),"") -> SR.26.09.0010/IX/2026/PGT/IT/INT
A9: =IF(tbl_computer[[#This Row],[No Asset]]<>"",SUBTOTAL(3,INDEX(tbl_computer[No Asset],1):tbl_computer[[#This Row],[No Asset]]),"") -> 0 | B9: =IF(OR(tbl_computer[[#This Row],[Purchase Date]]="",tbl_computer[[#This Row],[Categories]]=""),"", TEXT(tbl_computer[[#This Row],[Purchase Date]],"YYMM")& _xlfn.XLOOKUP(tbl_computer[[#This Row],[Categories]],CODEX!$Z:$Z,CODEX!$W:$W,"")& TEXT(_xlfn.XLOOKUP(tbl_computer[[#This Row],[Categories]],CODEX!$Z:$Z,CODEX!$Y:$Y,""),"00")& TEXT(COUNTIFS(INDEX(tbl_computer[Purchase Date],1):tbl_computer[[#This Row],[Purchase Date]],">="&DATE(YEAR(tbl_computer[[#This Row],[Purchase Date]]),MONTH(tbl_computer[[#This Row],[Purchase Date]]),1),INDEX(tbl_computer[Purchase Date],1):tbl_computer[[#This Row],[Purchase Date]],"<"&EDATE(DATE(YEAR(tbl_computer[[#This Row],[Purchase Date]]),MONTH(tbl_computer[[#This Row],[Purchase Date]]),1),1),INDEX(tbl_computer[Categories],1):tbl_computer[[#This Row],[Categories]],tbl_computer[[#This Row],[Categories]]),"000")) -> 2609101006 | C9: 46268 | D9: PO-002 | E9: Patimban | F9: Customs Gate-Out | G9: Computer | H9: PC | I9: HP ProDesk 4 Mini G1i Desktop AI PC | J9: MFF PC | K9: 8CC6062FST | L9: HP | M9: ProDesk 4 Mini G1i | O9: PBPCIT-GATEOUT | P9: W 11 Pro | Q9: D88W6-NVTMG-JWHRH-X4Y6J-CPQPM | R9: 10.90.10.96 | S9: N/A | T9: 44-25-38-33-F0-D5 | U9: B4-E2-5B-72-45-C7 | V9: INTEL | W9: Ultra 5 225T | X9: Intel(R) Core(TM) Ultra 5 225T (2.50 GHz) | Y9: Samsung | Z9: DDR5 | AA9: 5600 | AB9: 2 | AC9: Dual Chanel | AD9: 16 | AE9: Intel ARC Graphics | AF9: Y | AG9: SAMSUNG | AH9: SSD-NVME | AI9: 512 | AJ9: IPS Full HD (1920×1080) – 120 Hz | AK9: F27F320GA | AL9: 27" | AM9: New | AN9: PGT | AO9: IT | AP9: In used by User | AQ9: Exchange to PBPCHS-GATEOUT; Asset allocation for Customs in PGT | AU9: TRUE | AV9: =_xlfn.IFNA(INDEX(tbl_handover[No. Handover],MATCH(tbl_computer[[#This Row],[No Asset]],tbl_handover[Asset Code],0)),"")
A10: =IF(tbl_computer[[#This Row],[No Asset]]<>"",SUBTOTAL(3,INDEX(tbl_computer[No Asset],1):tbl_computer[[#This Row],[No Asset]]),"") -> 0 | B10: =IF(OR(tbl_computer[[#This Row],[Purchase Date]]="",tbl_computer[[#This Row],[Categories]]=""),"", TEXT(tbl_computer[[#This Row],[Purchase Date]],"YYMM")& _xlfn.XLOOKUP(tbl_computer[[#This Row],[Categories]],CODEX!$Z:$Z,CODEX!$W:$W,"")& TEXT(_xlfn.XLOOKUP(tbl_computer[[#This Row],[Categories]],CODEX!$Z:$Z,CODEX!$Y:$Y,""),"00")& TEXT(COUNTIFS(INDEX(tbl_computer[Purchase Date],1):tbl_computer[[#This Row],[Purchase Date]],">="&DATE(YEAR(tbl_computer[[#This Row],[Purchase Date]]),MONTH(tbl_computer[[#This Row],[Purchase Date]]),1),INDEX(tbl_computer[Purchase Date],1):tbl_computer[[#This Row],[Purchase Date]],"<"&EDATE(DATE(YEAR(tbl_computer[[#This Row],[Purchase Date]]),MONTH(tbl_computer[[#This Row],[Purchase Date]]),1),1),INDEX(tbl_computer[Categories],1):tbl_computer[[#This Row],[Categories]],tbl_computer[[#This Row],[Categories]]),"000")) -> 2609101007 | C10: 46268 | D10: PO-002 | E10: Patimban | F10: Customs Gate-In | G10: Computer | H10: PC | I10: HP ProDesk 4 Mini G1i Desktop AI PC | J10: MFF PC | K10: 8CC6062FV2 | L10: HP | M10: ProDesk 4 Mini G1i | O10: PBPCIT-GATEIN | P10: W 11 Pro | Q10: M273T-6NJC7-BCMVG-X69G9-9HJ6B | R10: 10.90.10.98 | S10: N/A | T10: 44-25-38-33-79-07 | U10: B4-E2-5B-72-44-5C | V10: INTEL | W10: Ultra 5 225T | X10: Intel(R) Core(TM) Ultra 5 225T (2.50 GHz) | Y10: Samsung | Z10: DDR5 | AA10: 5600 | AB10: 2 | AC10: Dual Chanel | AD10: 16 | AE10: Intel ARC Graphics | AF10: Y | AG10: SAMSUNG | AH10: SSD-NVME | AI10: 512 | AM10: New | AN10: PGT | AO10: IT | AP10: In used by User | AQ10: Asset allocation for Customs in PGT | AU10: FALSE | AV10: =_xlfn.IFNA(INDEX(tbl_handover[No. Handover],MATCH(tbl_computer[[#This Row],[No Asset]],tbl_handover[Asset Code],0)),"")
A11: =IF(tbl_computer[[#This Row],[No Asset]]<>"",SUBTOTAL(3,INDEX(tbl_computer[No Asset],1):tbl_computer[[#This Row],[No Asset]]),"") -> 0 | B11: =IF(OR(tbl_computer[[#This Row],[Purchase Date]]="",tbl_computer[[#This Row],[Categories]]=""),"", TEXT(tbl_computer[[#This Row],[Purchase Date]],"YYMM")& _xlfn.XLOOKUP(tbl_computer[[#This Row],[Categories]],CODEX!$Z:$Z,CODEX!$W:$W,"")& TEXT(_xlfn.XLOOKUP(tbl_computer[[#This Row],[Categories]],CODEX!$Z:$Z,CODEX!$Y:$Y,""),"00")& TEXT(COUNTIFS(INDEX(tbl_computer[Purchase Date],1):tbl_computer[[#This Row],[Purchase Date]],">="&DATE(YEAR(tbl_computer[[#This Row],[Purchase Date]]),MONTH(tbl_computer[[#This Row],[Purchase Date]]),1),INDEX(tbl_computer[Purchase Date],1):tbl_computer[[#This Row],[Purchase Date]],"<"&EDATE(DATE(YEAR(tbl_computer[[#This Row],[Purchase Date]]),MONTH(tbl_computer[[#This Row],[Purchase Date]]),1),1),INDEX(tbl_computer[Categories],1):tbl_computer[[#This Row],[Categories]],tbl_computer[[#This Row],[Categories]]),"000")) -> 2601101002 | C11: 46023 | D11: PO-001 | E11: Patimban | F11: Equipment Room | G11: Computer | H11: PC | I11: Dell Pro Micro QCM1250 | J11: MFF PC | K11: FLYZHC4 | L11: DELL | M11: Pro Micro QCM1250 | O11: PBPCEQ-TIRTA | P11: W 11 Pro | Q11: W3MGP-NWGJ2-349TB-6W9RJ-RX9CT | S11: N/A | T11: FC-4C-EA-11-2D-54 | U11: C0-A8-10-1D-2E-EB | V11: INTEL | W11: i5-14500T | X11: Intel(R) Core(TM) i5-14500T (1.70 GHz) | Y11: Samsung | Z11: DDR5 | AA11: 5600 | AB11: 2 | AC11: Dual Chanel | AD11: 16 | AF11: Y | AH11: SSD-NVME | AI11: 512 | AM11: Good | AN11: PGT | AO11: IT | AP11: In used by User | AU11: FALSE | AV11: =_xlfn.IFNA(INDEX(tbl_handover[No. Handover],MATCH(tbl_computer[[#This Row],[No Asset]],tbl_handover[Asset Code],0)),"")
A12: =IF(tbl_computer[[#This Row],[No Asset]]<>"",SUBTOTAL(3,INDEX(tbl_computer[No Asset],1):tbl_computer[[#This Row],[No Asset]]),"") -> 0 | B12: =IF(OR(tbl_computer[[#This Row],[Purchase Date]]="",tbl_computer[[#This Row],[Categories]]=""),"", TEXT(tbl_computer[[#This Row],[Purchase Date]],"YYMM")& _xlfn.XLOOKUP(tbl_computer[[#This Row],[Categories]],CODEX!$Z:$Z,CODEX!$W:$W,"")& TEXT(_xlfn.XLOOKUP(tbl_computer[[#This Row],[Categories]],CODEX!$Z:$Z,CODEX!$Y:$Y,""),"00")& TEXT(COUNTIFS(INDEX(tbl_computer[Purchase Date],1):tbl_computer[[#This Row],[Purchase Date]],">="&DATE(YEAR(tbl_computer[[#This Row],[Purchase Date]]),MONTH(tbl_computer[[#This Row],[Purchase Date]]),1),INDEX(tbl_computer[Purchase Date],1):tbl_computer[[#This Row],[Purchase Date]],"<"&EDATE(DATE(YEAR(tbl_computer[[#This Row],[Purchase Date]]),MONTH(tbl_computer[[#This Row],[Purchase Date]]),1),1),INDEX(tbl_computer[Categories],1):tbl_computer[[#This Row],[Categories]],tbl_computer[[#This Row],[Categories]]),"000")) -> 2601101003 | C12: 46023 | D12: PO-001 | E12: Patimban | F12: Labour Room | G12: Computer | H12: PC | I12: Dell Pro Micro QCM1250 | J12: MFF PC | K12: CNYZHC4 | L12: DELL | M12: Pro Micro QCM1250 | O12: PBPCOP-LABOUR1 | P12: W 11 Pro | Q12: T494N-JBXDH-7DHM6-MW9W6-HFTPT | S12: N/A | T12: FC-4C-EA-11-2D-20 | U12: C0-A8-10-1D-2E-E1 | V12: INTEL | W12: i5-14500T | X12: Intel(R) Core(TM) i5-14500T (1.70 GHz) | Y12: Samsung | Z12: DDR5 | AA12: 5600 | AB12: 2 | AC12: Dual Chanel | AD12: 16 | AF12: Y | AH12: SSD-NVME | AI12: 512 | AM12: Good | AN12: PGT | AO12: IT | AP12: In used by User | AU12: TRUE | AV12: =_xlfn.IFNA(INDEX(tbl_handover[No. Handover],MATCH(tbl_computer[[#This Row],[No Asset]],tbl_handover[Asset Code],0)),"")
A13: =IF(tbl_computer[[#This Row],[No Asset]]<>"",SUBTOTAL(3,INDEX(tbl_computer[No Asset],1):tbl_computer[[#This Row],[No Asset]]),"") -> 0 | B13: =IF(OR(tbl_computer[[#This Row],[Purchase Date]]="",tbl_computer[[#This Row],[Categories]]=""),"", TEXT(tbl_computer[[#This Row],[Purchase Date]],"YYMM")& _xlfn.XLOOKUP(tbl_computer[[#This Row],[Categories]],CODEX!$Z:$Z,CODEX!$W:$W,"")& TEXT(_xlfn.XLOOKUP(tbl_computer[[#This Row],[Categories]],CODEX!$Z:$Z,CODEX!$Y:$Y,""),"00")& TEXT(COUNTIFS(INDEX(tbl_computer[Purchase Date],1):tbl_computer[[#This Row],[Purchase Date]],">="&DATE(YEAR(tbl_computer[[#This Row],[Purchase Date]]),MONTH(tbl_computer[[#This Row],[Purchase Date]]),1),INDEX(tbl_computer[Purchase Date],1):tbl_computer[[#This Row],[Purchase Date]],"<"&EDATE(DATE(YEAR(tbl_computer[[#This Row],[Purchase Date]]),MONTH(tbl_computer[[#This Row],[Purchase Date]]),1),1),INDEX(tbl_computer[Categories],1):tbl_computer[[#This Row],[Categories]],tbl_computer[[#This Row],[Categories]]),"000")) -> 2601101004 | C13: 46023 | D13: PO-001 | E13: Patimban | F13: HSE Room | G13: Computer | H13: PC | I13: HP Pro Mini PC 400 G9 | J13: MFF PC | K13: 8CC6090X4V | L13: HP | M13: Pro Mini PC 400 G9 | O13: PBPCHS-HSSE | P13: W 11 Pro | S13: N/A | T13: EC-3A-56-75-AC-C2 | U13: B4-E2-5B-77-5C-9E | V13: INTEL | W13: Core i7 14700T | X13: Core(TM) i7-14700T (1.30 GHz) | Y13: Samsung | Z13: DDR5 | AA13: 5600 | AB13: 2 | AC13: Dual Chanel | AD13: 16 | AE13: UHD Graphics 770 | AF13: Y | AG13: KIOXIA | AH13: SSD-NVME | AI13: 1024 | AL13: 27" | AM13: Good | AN13: PGT | AO13: IT | AP13: Shared | AQ13: For CCTV display in HSSE room | AU13: TRUE | AV13: =_xlfn.IFNA(INDEX(tbl_handover[No. Handover],MATCH(tbl_computer[[#This Row],[No Asset]],tbl_handover[Asset Code],0)),"") -> SR.26.09.0011/IX/2026/PGT/IT/INT
A14: =IF(tbl_computer[[#This Row],[No Asset]]<>"",SUBTOTAL(3,INDEX(tbl_computer[No Asset],1):tbl_computer[[#This Row],[No Asset]]),"") -> 0 | B14: =IF(OR(tbl_computer[[#This Row],[Purchase Date]]="",tbl_computer[[#This Row],[Categories]]=""),"", TEXT(tbl_computer[[#This Row],[Purchase Date]],"YYMM")& _xlfn.XLOOKUP(tbl_computer[[#This Row],[Categories]],CODEX!$Z:$Z,CODEX!$W:$W,"")& TEXT(_xlfn.XLOOKUP(tbl_computer[[#This Row],[Categories]],CODEX!$Z:$Z,CODEX!$Y:$Y,""),"00")& TEXT(COUNTIFS(INDEX(tbl_computer[Purchase Date],1):tbl_computer[[#This Row],[Purchase Date]],">="&DATE(YEAR(tbl_computer[[#This Row],[Purchase Date]]),MONTH(tbl_computer[[#This Row],[Purchase Date]]),1),INDEX(tbl_computer[Purchase Date],1):tbl_computer[[#This Row],[Purchase Date]],"<"&EDATE(DATE(YEAR(tbl_computer[[#This Row],[Purchase Date]]),MONTH(tbl_computer[[#This Row],[Purchase Date]]),1),1),INDEX(tbl_computer[Categories],1):tbl_computer[[#This Row],[Categories]],tbl_computer[[#This Row],[Categories]]),"000")) -> 2601101005 | C14: 46023 | D14: PO-001 | E14: Patimban | F14: Operations Room | G14: Computer | H14: PC | I14: Dell Pro Micro QCM1250 | J14: MFF PC | K14: 11N0JC4 | L14: DELL | M14: Pro Micro QCM1250 | O14: PBPCOP-BERTHING | P14: W 11 Pro | Q14: QR44C-N7QHM-TV7YP-97P8T-6F4TG | R14: 10.90.10.129 | S14: N/A | T14: C0-A8-10-30-81-85 | U14: FC-4C-EA-10-9C-2E | V14: INTEL | W14: i5-14500T | X14: Core(TM)i5-14500T (1.70 GHz) | Y14: Samsung | Z14: DDR5 | AA14: 5600 | AB14: 2 | AC14: Dual Chanel | AD14: 16 | AE14: UHD Graphics 770 | AF14: Y | AG14: KIOXIA | AH14: SSD-NVME | AI14: 512 | AJ14: Samsung Curved 32" S32D396GAE | AK14: Curve | AL14: 32" | AM14: Good | AN14: PGT | AO14: IT | AP14: In used by User | AU14: TRUE | AV14: =_xlfn.IFNA(INDEX(tbl_handover[No. Handover],MATCH(tbl_computer[[#This Row],[No Asset]],tbl_handover[Asset Code],0)),"")
A15: =IF(tbl_computer[[#This Row],[No Asset]]<>"",SUBTOTAL(3,INDEX(tbl_computer[No Asset],1):tbl_computer[[#This Row],[No Asset]]),"") -> 0 | B15: =IF(OR(tbl_computer[[#This Row],[Purchase Date]]="",tbl_computer[[#This Row],[Categories]]=""),"", TEXT(tbl_computer[[#This Row],[Purchase Date]],"YYMM")& _xlfn.XLOOKUP(tbl_computer[[#This Row],[Categories]],CODEX!$Z:$Z,CODEX!$W:$W,"")& TEXT(_xlfn.XLOOKUP(tbl_computer[[#This Row],[Categories]],CODEX!$Z:$Z,CODEX!$Y:$Y,""),"00")& TEXT(COUNTIFS(INDEX(tbl_computer[Purchase Date],1):tbl_computer[[#This Row],[Purchase Date]],">="&DATE(YEAR(tbl_computer[[#This Row],[Purchase Date]]),MONTH(tbl_computer[[#This Row],[Purchase Date]]),1),INDEX(tbl_computer[Purchase Date],1):tbl_computer[[#This Row],[Purchase Date]],"<"&EDATE(DATE(YEAR(tbl_computer[[#This Row],[Purchase Date]]),MONTH(tbl_computer[[#This Row],[Purchase Date]]),1),1),INDEX(tbl_computer[Categories],1):tbl_computer[[#This Row],[Categories]],tbl_computer[[#This Row],[Categories]]),"000")) -> 2601101006 | C15: 46023 | D15: PO-001 | E15: Patimban | F15: Operations Room | G15: Computer | H15: PC | I15: Dell Pro Micro QCM1250 | J15: MFF PC | K15: 91N0JC4 | L15: DELL | M15: Pro Micro QCM1250 | O15: PBPCOP-YARD | P15: W 11 Pro | Q15: D9WNB-H36DJ-4M2J9-6V94R-MWRTG | S15: N/A | T15: 86-47-21-9B-E7-75 | U15: FC-4C-EA-11-46-A4 | V15: INTEL | W15: i5-14500T | X15: Core(TM)i5-14500T (1.70 GHz) | Y15: Samsung | Z15: DDR5 | AA15: 5600 | AB15: 2 | AC15: Dual Chanel | AD15: 16 | AE15: UHD Graphics 770 | AF15: Y | AG15: KIOXIA | AH15: SSD-NVME | AI15: 512 | AJ15: Samsung Curved 32" S32D396GAE | AK15: Curve | AL15: 32" | AM15: Good | AN15: PGT | AO15: IT | AP15: In used by User | AU15: TRUE | AV15: =_xlfn.IFNA(INDEX(tbl_handover[No. Handover],MATCH(tbl_computer[[#This Row],[No Asset]],tbl_handover[Asset Code],0)),"")
A16: =IF(tbl_computer[[#This Row],[No Asset]]<>"",SUBTOTAL(3,INDEX(tbl_computer[No Asset],1):tbl_computer[[#This Row],[No Asset]]),"") -> 0 | B16: =IF(OR(tbl_computer[[#This Row],[Purchase Date]]="",tbl_computer[[#This Row],[Categories]]=""),"", TEXT(tbl_computer[[#This Row],[Purchase Date]],"YYMM")& _xlfn.XLOOKUP(tbl_computer[[#This Row],[Categories]],CODEX!$Z:$Z,CODEX!$W:$W,"")& TEXT(_xlfn.XLOOKUP(tbl_computer[[#This Row],[Categories]],CODEX!$Z:$Z,CODEX!$Y:$Y,""),"00")& TEXT(COUNTIFS(INDEX(tbl_computer[Purchase Date],1):tbl_computer[[#This Row],[Purchase Date]],">="&DATE(YEAR(tbl_computer[[#This Row],[Purchase Date]]),MONTH(tbl_computer[[#This Row],[Purchase Date]]),1),INDEX(tbl_computer[Purchase Date],1):tbl_computer[[#This Row],[Purchase Date]],"<"&EDATE(DATE(YEAR(tbl_computer[[#This Row],[Purchase Date]]),MONTH(tbl_computer[[#This Row],[Purchase Date]]),1),1),INDEX(tbl_computer[Categories],1):tbl_computer[[#This Row],[Categories]],tbl_computer[[#This Row],[Categories]]),"000")) -> 2601101007 | C16: 46023 | D16: PO-001 | E16: Patimban | F16: Operations Room | G16: Computer | H16: PC | I16: Dell Pro Micro QCM1250 | J16: MFF PC | K16: G0N0JC4 | L16: DELL | M16: Pro Micro QCM1250 | O16: PBPCOP-SHIPPLANNER | P16: W 11 Pro | Q16: BFCWM-6NPQG-CJ4Y4-XVPJM-3GP2T | S16: N/A | T16: C0-A8-10-30-50-B6 | U16: FC-4C-EA-10-AB-9C | V16: INTEL | W16: i5-14500T | X16: Core(TM)i5-14500T (1.70 GHz) | Y16: Samsung | Z16: DDR5 | AA16: 5600 | AB16: 2 | AC16: Dual Chanel | AD16: 16 | AE16: UHD Graphics 770 | AF16: Y | AG16: KIOXIA | AH16: SSD-NVME | AI16: 512 | AJ16: Samsung Curved 32" S32D396GAE | AK16: Curve | AL16: 32" | AM16: Good | AN16: PGT | AO16: IT | AP16: In used by User | AU16: TRUE | AV16: =_xlfn.IFNA(INDEX(tbl_handover[No. Handover],MATCH(tbl_computer[[#This Row],[No Asset]],tbl_handover[Asset Code],0)),"")
A17: =IF(tbl_computer[[#This Row],[No Asset]]<>"",SUBTOTAL(3,INDEX(tbl_computer[No Asset],1):tbl_computer[[#This Row],[No Asset]]),"") -> 0 | B17: =IF(OR(tbl_computer[[#This Row],[Purchase Date]]="",tbl_computer[[#This Row],[Categories]]=""),"", TEXT(tbl_computer[[#This Row],[Purchase Date]],"YYMM")& _xlfn.XLOOKUP(tbl_computer[[#This Row],[Categories]],CODEX!$Z:$Z,CODEX!$W:$W,"")& TEXT(_xlfn.XLOOKUP(tbl_computer[[#This Row],[Categories]],CODEX!$Z:$Z,CODEX!$Y:$Y,""),"00")& TEXT(COUNTIFS(INDEX(tbl_computer[Purchase Date],1):tbl_computer[[#This Row],[Purchase Date]],">="&DATE(YEAR(tbl_computer[[#This Row],[Purchase Date]]),MONTH(tbl_computer[[#This Row],[Purchase Date]]),1),INDEX(tbl_computer[Purchase Date],1):tbl_computer[[#This Row],[Purchase Date]],"<"&EDATE(DATE(YEAR(tbl_computer[[#This Row],[Purchase Date]]),MONTH(tbl_computer[[#This Row],[Purchase Date]]),1),1),INDEX(tbl_computer[Categories],1):tbl_computer[[#This Row],[Categories]],tbl_computer[[#This Row],[Categories]]),"000")) -> 2601101008 | C17: 46023 | D17: PO-001 | E17: Patimban | F17: Loket Room | G17: Computer | H17: PC | I17: Dell Pro Micro QCM1250 | J17: MFF PC | K17: 70N0JCA | L17: DELL | M17: Pro Micro QCM1250 | O17: PBPCCO-LOCKETSTAFF | P17: W 11 Pro | Q17: T9NCH-M7RWZ-6YKJ2-66FKD-4GDW6 | R17: N/A | S17: 192.168.101.181 | T17: C0-A8-10-30-50-DE | U17: FC-4C-EA-10-F2-6C | V17: INTEL | W17: i5-14500T | X17: Core(TM)i5-14500T (1.70 GHz) | Y17: Samsung | Z17: DDR5 | AA17: 5600 | AB17: 2 | AC17: Dual Chanel | AD17: 16 | AE17: UHD Graphics 770 | AF17: Y | AG17: KIOXIA | AH17: SSD-NVME | AI17: 512 | AJ17: Samsung Curved 32" S32D396GAE | AK17: Curve | AL17: 32" | AM17: Good | AN17: PGT | AO17: IT | AP17: In used by User | AQ17: Used by locket staff | AU17: FALSE | AV17: =_xlfn.IFNA(INDEX(tbl_handover[No. Handover],MATCH(tbl_computer[[#This Row],[No Asset]],tbl_handover[Asset Code],0)),"")
A18: =IF(tbl_computer[[#This Row],[No Asset]]<>"",SUBTOTAL(3,INDEX(tbl_computer[No Asset],1):tbl_computer[[#This Row],[No Asset]]),"") -> 0 | B18: =IF(OR(tbl_computer[[#This Row],[Purchase Date]]="",tbl_computer[[#This Row],[Categories]]=""),"", TEXT(tbl_computer[[#This Row],[Purchase Date]],"YYMM")& _xlfn.XLOOKUP(tbl_computer[[#This Row],[Categories]],CODEX!$Z:$Z,CODEX!$W:$W,"")& TEXT(_xlfn.XLOOKUP(tbl_computer[[#This Row],[Categories]],CODEX!$Z:$Z,CODEX!$Y:$Y,""),"00")& TEXT(COUNTIFS(INDEX(tbl_computer[Purchase Date],1):tbl_computer[[#This Row],[Purchase Date]],">="&DATE(YEAR(tbl_computer[[#This Row],[Purchase Date]]),MONTH(tbl_computer[[#This Row],[Purchase Date]]),1),INDEX(tbl_computer[Purchase Date],1):tbl_computer[[#This Row],[Purchase Date]],"<"&EDATE(DATE(YEAR(tbl_computer[[#This Row],[Purchase Date]]),MONTH(tbl_computer[[#This Row],[Purchase Date]]),1),1),INDEX(tbl_computer[Categories],1):tbl_computer[[#This Row],[Categories]],tbl_computer[[#This Row],[Categories]]),"000")) -> 2601101009 | C18: 46023 | D18: PO-001 | E18: Patimban | F18: Engineer Room | G18: Computer | H18: AIO | I18: Axioo HYPE Flex X6 AIO | J18: AIO PC | K18: NPM23I34 | L18: AXIOO | M18: HYPE Flex X6 AIO | O18: Axioo HYPE Flex X6 | P18: W 11 Pro | R18: 192.168.100.13 | S18: N/A | T18: 9C:12:21:16:E2:86 | U18: 84-47-09-54-22-E3 | V18: AMD | W18: Ryzen 5 6600H | X18: Ryzen 5 6600H | Z18: DDR4 | AD18: 16 | AF18: Y | AG18: HIGHREAL | AH18: SSD-NVME | AI18: 512 | AM18: Service | AN18: PGT | AO18: IT | AP18: Idle | AU18: TRUE | AV18: =_xlfn.IFNA(INDEX(tbl_handover[No. Handover],MATCH(tbl_computer[[#This Row],[No Asset]],tbl_handover[Asset Code],0)),"")
A19: =IF(tbl_computer[[#This Row],[No Asset]]<>"",SUBTOTAL(3,INDEX(tbl_computer[No Asset],1):tbl_computer[[#This Row],[No Asset]]),"") -> 1 | B19: =IF(OR(tbl_computer[[#This Row],[Purchase Date]]="",tbl_computer[[#This Row],[Categories]]=""),"", TEXT(tbl_computer[[#This Row],[Purchase Date]],"YYMM")& _xlfn.XLOOKUP(tbl_computer[[#This Row],[Categories]],CODEX!$Z:$Z,CODEX!$W:$W,"")& TEXT(_xlfn.XLOOKUP(tbl_computer[[#This Row],[Categories]],CODEX!$Z:$Z,CODEX!$Y:$Y,""),"00")& TEXT(COUNTIFS(INDEX(tbl_computer[Purchase Date],1):tbl_computer[[#This Row],[Purchase Date]],">="&DATE(YEAR(tbl_computer[[#This Row],[Purchase Date]]),MONTH(tbl_computer[[#This Row],[Purchase Date]]),1),INDEX(tbl_computer[Purchase Date],1):tbl_computer[[#This Row],[Purchase Date]],"<"&EDATE(DATE(YEAR(tbl_computer[[#This Row],[Purchase Date]]),MONTH(tbl_computer[[#This Row],[Purchase Date]]),1),1),INDEX(tbl_computer[Categories],1):tbl_computer[[#This Row],[Categories]],tbl_computer[[#This Row],[Categories]]),"000")) -> 2601101010 | C19: 46023 | D19: PO-001 | E19: Patimban | F19: CY/Wharf Area | G19: Computer | H19: Handheld | I19: Samsung Galaxy Tab Active5 | J19: TABLET | K19: RRGYC03GBWD | L19: SAMSUNG | M19: Galaxy Tab Active5 | O19: PBTBOP-YOS2 | P19: Android | Q19: N/A | S19: N/A | T19: 08:10:93:5C:55:87 | U19: N/A | V19: SAMSUNG | W19: Exynos 1380 | X19: Chipset Samsung Exynos 1380, CPU octa-core | Y19: N/A | Z19: INTERNAL | AA19: N/A | AB19: N/A | AC19: N/A | AD19: 6 | AE19: N/A | AF19: N | AG19: N/A | AH19: N/A | AI19: 128 | AJ19: TFT LCD (1920 x 1200) - 120Hz | AK19: WUXGA | AL19: 8" | AM19: Good | AN19: PGT | AO19: IT | AP19: In used by User | AQ19: Include Anker Zolo charger (20w,PD 3.0); ex. Gate staff (PBTABGS-GATE IN); in used by YOS-2 | AU19: TRUE | AV19: =_xlfn.IFNA(INDEX(tbl_handover[No. Handover],MATCH(tbl_computer[[#This Row],[No Asset]],tbl_handover[Asset Code],0)),"")
A20: =IF(tbl_computer[[#This Row],[No Asset]]<>"",SUBTOTAL(3,INDEX(tbl_computer[No Asset],1):tbl_computer[[#This Row],[No Asset]]),"") -> 2 | B20: =IF(OR(tbl_computer[[#This Row],[Purchase Date]]="",tbl_computer[[#This Row],[Categories]]=""),"", TEXT(tbl_computer[[#This Row],[Purchase Date]],"YYMM")& _xlfn.XLOOKUP(tbl_computer[[#This Row],[Categories]],CODEX!$Z:$Z,CODEX!$W:$W,"")& TEXT(_xlfn.XLOOKUP(tbl_computer[[#This Row],[Categories]],CODEX!$Z:$Z,CODEX!$Y:$Y,""),"00")& TEXT(COUNTIFS(INDEX(tbl_computer[Purchase Date],1):tbl_computer[[#This Row],[Purchase Date]],">="&DATE(YEAR(tbl_computer[[#This Row],[Purchase Date]]),MONTH(tbl_computer[[#This Row],[Purchase Date]]),1),INDEX(tbl_computer[Purchase Date],1):tbl_computer[[#This Row],[Purchase Date]],"<"&EDATE(DATE(YEAR(tbl_computer[[#This Row],[Purchase Date]]),MONTH(tbl_computer[[#This Row],[Purchase Date]]),1),1),INDEX(tbl_computer[Categories],1):tbl_computer[[#This Row],[Categories]],tbl_computer[[#This Row],[Categories]]),"000")) -> 2601101011 | C20: 46023 | D20: PO-001 | E20: Patimban | F20: CY/Wharf Area | G20: Computer | H20: Handheld | I20: Samsung Galaxy Tab Active5 | J20: TABLET | K20: RRGYC03GCWT | L20: SAMSUNG | M20: Galaxy Tab Active5 | O20: PBTABWS-WOS-1 | P20: Android | Q20: N/A | S20: N/A | T20: 08:10:93:5C:55:C9 | U20: N/A | V20: SAMSUNG | W20: Exynos 1380 | X20: Chipset Samsung Exynos 1380, CPU octa-core | Y20: N/A | Z20: INTERNAL | AA20: N/A | AB20: N/A | AC20: N/A | AD20: 6 | AE20: N/A | AF20: N | AG20: N/A | AH20: N/A | AI20: 128 | AJ20: TFT LCD (1920 x 1200) - 120Hz | AK20: WUXGA | AL20: 8" | AM20: Good | AN20: PGT | AO20: IT | AP20: In used by User | AQ20: Include Anker Zolo charger (20w,PD 3.0) | AU20: FALSE | AV20: =_xlfn.IFNA(INDEX(tbl_handover[No. Handover],MATCH(tbl_computer[[#This Row],[No Asset]],tbl_handover[Asset Code],0)),"")
A21: =IF(tbl_computer[[#This Row],[No Asset]]<>"",SUBTOTAL(3,INDEX(tbl_computer[No Asset],1):tbl_computer[[#This Row],[No Asset]]),"") -> 3 | B21: =IF(OR(tbl_computer[[#This Row],[Purchase Date]]="",tbl_computer[[#This Row],[Categories]]=""),"", TEXT(tbl_computer[[#This Row],[Purchase Date]],"YYMM")& _xlfn.XLOOKUP(tbl_computer[[#This Row],[Categories]],CODEX!$Z:$Z,CODEX!$W:$W,"")& TEXT(_xlfn.XLOOKUP(tbl_computer[[#This Row],[Categories]],CODEX!$Z:$Z,CODEX!$Y:$Y,""),"00")& TEXT(COUNTIFS(INDEX(tbl_computer[Purchase Date],1):tbl_computer[[#This Row],[Purchase Date]],">="&DATE(YEAR(tbl_computer[[#This Row],[Purchase Date]]),MONTH(tbl_computer[[#This Row],[Purchase Date]]),1),INDEX(tbl_computer[Purchase Date],1):tbl_computer[[#This Row],[Purchase Date]],"<"&EDATE(DATE(YEAR(tbl_computer[[#This Row],[Purchase Date]]),MONTH(tbl_computer[[#This Row],[Purchase Date]]),1),1),INDEX(tbl_computer[Categories],1):tbl_computer[[#This Row],[Categories]],tbl_computer[[#This Row],[Categories]]),"000")) -> 2601101012 | C21: 46023 | D21: PO-001 | E21: Patimban | F21: CY/Wharf Area | G21: Computer | H21: Handheld | I21: Samsung Galaxy Tab Active5 | J21: TABLET | K21: RRGYC03GCWI | L21: SAMSUNG | M21: Galaxy Tab Active5 | O21: PBTABWS-WOS-1 | P21: Android | Q21: N/A | S21: N/A | U21: N/A | V21: SAMSUNG | W21: Exynos 1380 | X21: Chipset Samsung Exynos 1380, CPU octa-core | Y21: N/A | Z21: INTERNAL | AA21: N/A | AB21: N/A | AC21: N/A | AD21: 6 | AE21: N/A | AF21: N | AG21: N/A | AH21: N/A | AI21: 128 | AJ21: TFT LCD (1920 x 1200) - 120Hz | AK21: WUXGA | AL21: 8" | AM21: Good | AN21: PGT | AO21: IT | AP21: In used by User | AQ21: Include Anker Zolo charger (20w,PD 3.0) | AU21: FALSE | AV21: =_xlfn.IFNA(INDEX(tbl_handover[No. Handover],MATCH(tbl_computer[[#This Row],[No Asset]],tbl_handover[Asset Code],0)),"")
A22: =IF(tbl_computer[[#This Row],[No Asset]]<>"",SUBTOTAL(3,INDEX(tbl_computer[No Asset],1):tbl_computer[[#This Row],[No Asset]]),"") -> 4 | B22: =IF(OR(tbl_computer[[#This Row],[Purchase Date]]="",tbl_computer[[#This Row],[Categories]]=""),"", TEXT(tbl_computer[[#This Row],[Purchase Date]],"YYMM")& _xlfn.XLOOKUP(tbl_computer[[#This Row],[Categories]],CODEX!$Z:$Z,CODEX!$W:$W,"")& TEXT(_xlfn.XLOOKUP(tbl_computer[[#This Row],[Categories]],CODEX!$Z:$Z,CODEX!$Y:$Y,""),"00")& TEXT(COUNTIFS(INDEX(tbl_computer[Purchase Date],1):tbl_computer[[#This Row],[Purchase Date]],">="&DATE(YEAR(tbl_computer[[#This Row],[Purchase Date]]),MONTH(tbl_computer[[#This Row],[Purchase Date]]),1),INDEX(tbl_computer[Purchase Date],1):tbl_computer[[#This Row],[Purchase Date]],"<"&EDATE(DATE(YEAR(tbl_computer[[#This Row],[Purchase Date]]),MONTH(tbl_computer[[#This Row],[Purchase Date]]),1),1),INDEX(tbl_computer[Categories],1):tbl_computer[[#This Row],[Categories]],tbl_computer[[#This Row],[Categories]]),"000")) -> 2601101013 | C22: 46023 | D22: PO-001 | E22: Patimban | F22: CY/Wharf Area | G22: Computer | H22: Handheld | I22: Samsung Galaxy Tab Active5 Pro | J22: TABLET | K22: RRGYC03GCWU | L22: SAMSUNG | M22: Galaxy Tab Active5 Pro | O22: PBTABEH-ECH101 | P22: Android | Q22: N/A | S22: N/A | U22: N/A | V22: QUALCOMM | W22: Snapdragon 7s Gen 3 | X22: Qualcomm Snapdragon 7s Gen 3 (4nm) | Y22: N/A | Z22: INTERNAL | AA22: N/A | AB22: N/A | AC22: N/A | AD22: 8 | AE22: N/A | AF22: N | AG22: N/A | AH22: N/A | AI22: 256 | AJ22: TFT LCD (1920 x 1200) - 120Hz | AK22: WUXGA | AL22: 10" | AM22: Good | AN22: PGT | AO22: IT | AP22: In used by User | AQ22: Include UGREEN USB to type C 3 Meter | AU22: TRUE | AV22: =_xlfn.IFNA(INDEX(tbl_handover[No. Handover],MATCH(tbl_computer[[#This Row],[No Asset]],tbl_handover[Asset Code],0)),"")
A23: =IF(tbl_computer[[#This Row],[No Asset]]<>"",SUBTOTAL(3,INDEX(tbl_computer[No Asset],1):tbl_computer[[#This Row],[No Asset]]),"") -> 5 | B23: =IF(OR(tbl_computer[[#This Row],[Purchase Date]]="",tbl_computer[[#This Row],[Categories]]=""),"", TEXT(tbl_computer[[#This Row],[Purchase Date]],"YYMM")& _xlfn.XLOOKUP(tbl_computer[[#This Row],[Categories]],CODEX!$Z:$Z,CODEX!$W:$W,"")& TEXT(_xlfn.XLOOKUP(tbl_computer[[#This Row],[Categories]],CODEX!$Z:$Z,CODEX!$Y:$Y,""),"00")& TEXT(COUNTIFS(INDEX(tbl_computer[Purchase Date],1):tbl_computer[[#This Row],[Purchase Date]],">="&DATE(YEAR(tbl_computer[[#This Row],[Purchase Date]]),MONTH(tbl_computer[[#This Row],[Purchase Date]]),1),INDEX(tbl_computer[Purchase Date],1):tbl_computer[[#This Row],[Purchase Date]],"<"&EDATE(DATE(YEAR(tbl_computer[[#This Row],[Purchase Date]]),MONTH(tbl_computer[[#This Row],[Purchase Date]]),1),1),INDEX(tbl_computer[Categories],1):tbl_computer[[#This Row],[Categories]],tbl_computer[[#This Row],[Categories]]),"000")) -> 2601101014 | C23: 46023 | D23: PO-001 | E23: Patimban | F23: CY/Wharf Area | G23: Computer | H23: Handheld | I23: Samsung Galaxy Tab Active5 Pro | J23: TABLET | K23: RRGYC09N6MN | L23: SAMSUNG | M23: Galaxy Tab Active5 Pro | O23: PBTABRS-RS101 | P23: Android | Q23: N/A | S23: N/A | U23: N/A | V23: QUALCOMM | W23: Snapdragon 7s Gen 3 | X23: Qualcomm Snapdragon 7s Gen 3 (4nm) | Y23: N/A | Z23: INTERNAL | AA23: N/A | AB23: N/A | AC23: N/A | AD23: 8 | AE23: N/A | AF23: N | AG23: N/A | AH23: N/A | AI23: 256 | AJ23: TFT LCD (1920 x 1200) - 120Hz | AK23: WUXGA | AL23: 10" | AM23: Good | AN23: PGT | AO23: IT | AP23: In used by User | AQ23: Include UGREEN USB to type C 3 Meter | AU23: FALSE | AV23: =_xlfn.IFNA(INDEX(tbl_handover[No. Handover],MATCH(tbl_computer[[#This Row],[No Asset]],tbl_handover[Asset Code],0)),"")
A24: =IF(tbl_computer[[#This Row],[No Asset]]<>"",SUBTOTAL(3,INDEX(tbl_computer[No Asset],1):tbl_computer[[#This Row],[No Asset]]),"") -> 6 | B24: =IF(OR(tbl_computer[[#This Row],[Purchase Date]]="",tbl_computer[[#This Row],[Categories]]=""),"", TEXT(tbl_computer[[#This Row],[Purchase Date]],"YYMM")& _xlfn.XLOOKUP(tbl_computer[[#This Row],[Categories]],CODEX!$Z:$Z,CODEX!$W:$W,"")& TEXT(_xlfn.XLOOKUP(tbl_computer[[#This Row],[Categories]],CODEX!$Z:$Z,CODEX!$Y:$Y,""),"00")& TEXT(COUNTIFS(INDEX(tbl_computer[Purchase Date],1):tbl_computer[[#This Row],[Purchase Date]],">="&DATE(YEAR(tbl_computer[[#This Row],[Purchase Date]]),MONTH(tbl_computer[[#This Row],[Purchase Date]]),1),INDEX(tbl_computer[Purchase Date],1):tbl_computer[[#This Row],[Purchase Date]],"<"&EDATE(DATE(YEAR(tbl_computer[[#This Row],[Purchase Date]]),MONTH(tbl_computer[[#This Row],[Purchase Date]]),1),1),INDEX(tbl_computer[Categories],1):tbl_computer[[#This Row],[Categories]],tbl_computer[[#This Row],[Categories]]),"000")) -> 2601101015 | C24: 46023 | D24: PO-001 | E24: Patimban | F24: CY/Wharf Area | G24: Computer | H24: Handheld | I24: Samsung Galaxy Tab Active5 Pro | J24: TABLET | K24: RRGYC09N70E | L24: SAMSUNG | M24: Galaxy Tab Active5 Pro | O24: PBTABRS-RS102 | P24: Android | Q24: N/A | R24: 10.90.70.2 | S24: N/A | T24: 08-10-93-69-E9-DD | U24: N/A | V24: QUALCOMM | W24: Snapdragon 7s Gen 3 | X24: Qualcomm Snapdragon 7s Gen 3 (4nm) | Y24: N/A | Z24: INTERNAL | AA24: N/A | AB24: N/A | AC24: N/A | AD24: 8 | AE24: N/A | AF24: N | AG24: N/A | AH24: N/A | AI24: 256 | AJ24: TFT LCD (1920 x 1200) - 120Hz | AK24: WUXGA | AL24: 10" | AM24: Good | AN24: PGT | AO24: IT | AP24: In used by User | AQ24: Include UGREEN USB to type C 3 Meter | AU24: TRUE | AV24: =_xlfn.IFNA(INDEX(tbl_handover[No. Handover],MATCH(tbl_computer[[#This Row],[No Asset]],tbl_handover[Asset Code],0)),"")
A25: =IF(tbl_computer[[#This Row],[No Asset]]<>"",SUBTOTAL(3,INDEX(tbl_computer[No Asset],1):tbl_computer[[#This Row],[No Asset]]),"") -> 7 | B25: =IF(OR(tbl_computer[[#This Row],[Purchase Date]]="",tbl_computer[[#This Row],[Categories]]=""),"", TEXT(tbl_computer[[#This Row],[Purchase Date]],"YYMM")& _xlfn.XLOOKUP(tbl_computer[[#This Row],[Categories]],CODEX!$Z:$Z,CODEX!$W:$W,"")& TEXT(_xlfn.XLOOKUP(tbl_computer[[#This Row],[Categories]],CODEX!$Z:$Z,CODEX!$Y:$Y,""),"00")& TEXT(COUNTIFS(INDEX(tbl_computer[Purchase Date],1):tbl_computer[[#This Row],[Purchase Date]],">="&DATE(YEAR(tbl_computer[[#This Row],[Purchase Date]]),MONTH(tbl_computer[[#This Row],[Purchase Date]]),1),INDEX(tbl_computer[Purchase Date],1):tbl_computer[[#This Row],[Purchase Date]],"<"&EDATE(DATE(YEAR(tbl_computer[[#This Row],[Purchase Date]]),MONTH(tbl_computer[[#This Row],[Purchase Date]]),1),1),INDEX(tbl_computer[Categories],1):tbl_computer[[#This Row],[Categories]],tbl_computer[[#This Row],[Categories]]),"000")) -> 2601101016 | C25: 46023 | D25: PO-001 | E25: Patimban | F25: CY/Wharf Area | G25: Computer | H25: Handheld | I25: Samsung Galaxy Tab Active5 | J25: TABLET | K25: RRGYC03GCZD | L25: SAMSUNG | M25: Galaxy Tab Active5 | O25: PBTABGS-GATE OUT STAFF | P25: Android | Q25: N/A | S25: N/A | U25: N/A | V25: SAMSUNG | W25: Exynos 1380 | X25: Chipset Samsung Exynos 1380, CPU octa-core | Y25: N/A | Z25: INTERNAL | AA25: N/A | AB25: N/A | AC25: N/A | AD25: 6 | AE25: N/A | AF25: N | AG25: N/A | AH25: N/A | AI25: 128 | AJ25: TFT LCD (1920 x 1200) - 120Hz | AK25: WUXGA | AL25: 8" | AM25: Good | AN25: PGT | AO25: IT | AP25: In used by User | AQ25: Include Anker Zolo charger (20w,PD 3.0); ex. Gate staff (PBTABGS-GATE OUT STAFF); in used by ECH-102 operators | AU25: FALSE | AV25: =_xlfn.IFNA(INDEX(tbl_handover[No. Handover],MATCH(tbl_computer[[#This Row],[No Asset]],tbl_handover[Asset Code],0)),"")
A26: =IF(tbl_computer[[#This Row],[No Asset]]<>"",SUBTOTAL(3,INDEX(tbl_computer[No Asset],1):tbl_computer[[#This Row],[No Asset]]),"") -> 7 | B26: =IF(OR(tbl_computer[[#This Row],[Purchase Date]]="",tbl_computer[[#This Row],[Categories]]=""),"", TEXT(tbl_computer[[#This Row],[Purchase Date]],"YYMM")& _xlfn.XLOOKUP(tbl_computer[[#This Row],[Categories]],CODEX!$Z:$Z,CODEX!$W:$W,"")& TEXT(_xlfn.XLOOKUP(tbl_computer[[#This Row],[Categories]],CODEX!$Z:$Z,CODEX!$Y:$Y,""),"00")& TEXT(COUNTIFS(INDEX(tbl_computer[Purchase Date],1):tbl_computer[[#This Row],[Purchase Date]],">="&DATE(YEAR(tbl_computer[[#This Row],[Purchase Date]]),MONTH(tbl_computer[[#This Row],[Purchase Date]]),1),INDEX(tbl_computer[Purchase Date],1):tbl_computer[[#This Row],[Purchase Date]],"<"&EDATE(DATE(YEAR(tbl_computer[[#This Row],[Purchase Date]]),MONTH(tbl_computer[[#This Row],[Purchase Date]]),1),1),INDEX(tbl_computer[Categories],1):tbl_computer[[#This Row],[Categories]],tbl_computer[[#This Row],[Categories]]),"000")) -> 2601101017 | C26: 46023 | D26: PO-001 | E26: Patimban | F26: Equipment Room | G26: Computer | H26: Notebook | I26: Dell Pro 14 PC14250 | J26: NOTEBOOK | K26: BDVNND4 | L26: DELL | M26: Pro 14 PC14250 | O26: PBNBEQ-DIAN | P26: W 11 Pro | Q26: TM2FM-MQNJY-PGV4W-PYFM2-XTP2T | R26: 192.168.100.248 | S26: N/A | T26: E8-BF-E1-DC-7E-18 | U26: 84-5C-31-81-8F-DA | V26: INTEL | W26: Ultra 5 235U | X26: Intel(R) Core(TM) Ultra 5 235U (2.00 GHz) | Y26: Samsung | Z26: DDR5 | AA26: 5600 | AB26: 2 | AC26: Singgle Chanel | AD26: 16 | AE26: Intel ARC Graphics | AF26: Y | AG26: SAMSUNG | AH26: SSD-NVME | AI26: 512 | AL26: 11" | AM26: Good | AN26: PGT | AO26: IT | AP26: In used by User | AQ26: ex. PBNBIT-ITSTAFF | AU26: TRUE | AV26: =_xlfn.IFNA(INDEX(tbl_handover[No. Handover],MATCH(tbl_computer[[#This Row],[No Asset]],tbl_handover[Asset Code],0)),"") -> SR.26.09.0016/IX/2026/PGT/IT/INT
A27: =IF(tbl_computer[[#This Row],[No Asset]]<>"",SUBTOTAL(3,INDEX(tbl_computer[No Asset],1):tbl_computer[[#This Row],[No Asset]]),"") -> 7 | B27: =IF(OR(tbl_computer[[#This Row],[Purchase Date]]="",tbl_computer[[#This Row],[Categories]]=""),"", TEXT(tbl_computer[[#This Row],[Purchase Date]],"YYMM")& _xlfn.XLOOKUP(tbl_computer[[#This Row],[Categories]],CODEX!$Z:$Z,CODEX!$W:$W,"")& TEXT(_xlfn.XLOOKUP(tbl_computer[[#This Row],[Categories]],CODEX!$Z:$Z,CODEX!$Y:$Y,""),"00")& TEXT(COUNTIFS(INDEX(tbl_computer[Purchase Date],1):tbl_computer[[#This Row],[Purchase Date]],">="&DATE(YEAR(tbl_computer[[#This Row],[Purchase Date]]),MONTH(tbl_computer[[#This Row],[Purchase Date]]),1),INDEX(tbl_computer[Purchase Date],1):tbl_computer[[#This Row],[Purchase Date]],"<"&EDATE(DATE(YEAR(tbl_computer[[#This Row],[Purchase Date]]),MONTH(tbl_computer[[#This Row],[Purchase Date]]),1),1),INDEX(tbl_computer[Categories],1):tbl_computer[[#This Row],[Categories]],tbl_computer[[#This Row],[Categories]]),"000")) -> 2601101018 | C27: 46023 | D27: PO-001 | E27: Patimban | F27: AGL Office | G27: Computer | H27: Notebook | I27: Lenovo ThinkPad E14 Gen7 | J27: NOTEBOOK | K27: PF6LXC2 | L27: LENOVO | M27: Lenovo ThinkPad E14 Gen7 | O27: AGL | P27: W 11 Pro | Q27: TM3GM-WQNJY-GGIO4-PYFM2-XPP2G | S27: N/A | T27: F4-4E-B4-60-68-BF | U27: D4-A2-CD-F0-91-C2 | V27: INTEL | AD27: 16 | AF27: Y | AH27: SSD-NVME | AI27: 512 | AM27: Good | AN27: PGT | AO27: IT | AP27: Lent out | AQ27: Lent out to AGL staff (include Miniso mouse & laptop bag); Ex. Hangga | AU27: TRUE | AV27: =_xlfn.IFNA(INDEX(tbl_handover[No. Handover],MATCH(tbl_computer[[#This Row],[No Asset]],tbl_handover[Asset Code],0)),"")
A28: =IF(tbl_computer[[#This Row],[No Asset]]<>"",SUBTOTAL(3,INDEX(tbl_computer[No Asset],1):tbl_computer[[#This Row],[No Asset]]),"") -> 7 | B28: =IF(OR(tbl_computer[[#This Row],[Purchase Date]]="",tbl_computer[[#This Row],[Categories]]=""),"", TEXT(tbl_computer[[#This Row],[Purchase Date]],"YYMM")& _xlfn.XLOOKUP(tbl_computer[[#This Row],[Categories]],CODEX!$Z:$Z,CODEX!$W:$W,"")& TEXT(_xlfn.XLOOKUP(tbl_computer[[#This Row],[Categories]],CODEX!$Z:$Z,CODEX!$Y:$Y,""),"00")& TEXT(COUNTIFS(INDEX(tbl_computer[Purchase Date],1):tbl_computer[[#This Row],[Purchase Date]],">="&DATE(YEAR(tbl_computer[[#This Row],[Purchase Date]]),MONTH(tbl_computer[[#This Row],[Purchase Date]]),1),INDEX(tbl_computer[Purchase Date],1):tbl_computer[[#This Row],[Purchase Date]],"<"&EDATE(DATE(YEAR(tbl_computer[[#This Row],[Purchase Date]]),MONTH(tbl_computer[[#This Row],[Purchase Date]]),1),1),INDEX(tbl_computer[Categories],1):tbl_computer[[#This Row],[Categories]],tbl_computer[[#This Row],[Categories]]),"000")) -> 2601101019 | C28: 46023 | D28: PO-001 | E28: Patimban | F28: Gate Office | G28: Computer | H28: PC | I28: Dell Pro Micro QCM1250 | J28: MFF PC | K28: 60N0JC4 | L28: DELL | M28: Pro Micro QCM1250 | O28: PBPCOP-GATEIN | P28: W 11 Pro | Q28: BP6NY-H3KT4-H42QH-4WJ8C-D6986 | R28: N/A | S28: 192.168.101.182 | T28: C0-A8-10-30-8F-BD | U28: FC-4C-EA-10-F3-45 | V28: INTEL | W28: i5-14500T | X28: Core(TM)i5-14500T (1.70 GHz) | Y28: Samsung | Z28: DDR5 | AA28: 5600 | AB28: 2 | AC28: Dual Chanel | AD28: 16 | AE28: UHD Graphics 770 | AF28: Y | AG28: KIOXIA | AH28: SSD-NVME | AI28: 512 | AJ28: Samsung Curved 32" S32D396GAE | AK28: Curve | AL28: 32" | AM28: Good | AN28: PGT | AO28: IT | AP28: In used by User | AQ28: Used by gate staff | AU28: FALSE | AV28: =_xlfn.IFNA(INDEX(tbl_handover[No. Handover],MATCH(tbl_computer[[#This Row],[No Asset]],tbl_handover[Asset Code],0)),"")
A29: =IF(tbl_computer[[#This Row],[No Asset]]<>"",SUBTOTAL(3,INDEX(tbl_computer[No Asset],1):tbl_computer[[#This Row],[No Asset]]),"") -> 7 | B29: =IF(OR(tbl_computer[[#This Row],[Purchase Date]]="",tbl_computer[[#This Row],[Categories]]=""),"", TEXT(tbl_computer[[#This Row],[Purchase Date]],"YYMM")& _xlfn.XLOOKUP(tbl_computer[[#This Row],[Categories]],CODEX!$Z:$Z,CODEX!$W:$W,"")& TEXT(_xlfn.XLOOKUP(tbl_computer[[#This Row],[Categories]],CODEX!$Z:$Z,CODEX!$Y:$Y,""),"00")& TEXT(COUNTIFS(INDEX(tbl_computer[Purchase Date],1):tbl_computer[[#This Row],[Purchase Date]],">="&DATE(YEAR(tbl_computer[[#This Row],[Purchase Date]]),MONTH(tbl_computer[[#This Row],[Purchase Date]]),1),INDEX(tbl_computer[Purchase Date],1):tbl_computer[[#This Row],[Purchase Date]],"<"&EDATE(DATE(YEAR(tbl_computer[[#This Row],[Purchase Date]]),MONTH(tbl_computer[[#This Row],[Purchase Date]]),1),1),INDEX(tbl_computer[Categories],1):tbl_computer[[#This Row],[Categories]],tbl_computer[[#This Row],[Categories]]),"000")) -> 2601101020 | C29: 46023 | D29: PO-001 | E29: Patimban | F29: HSE Room | G29: Computer | H29: Notebook | I29: Dell Pro 14 PC14250 | J29: NOTEBOOK | K29: D8DJ6J4 | L29: DELL | M29: Pro 14 PC14250 | O29: PBNBIS-BAHTIAR | P29: W 11 Pro | Q29: HYN27-92RFV-4G4KM-4MDQ2-GQ8GG | S29: N/A | T29: 3C-EF-A5-F6-F7-F5 | U29: 94-10-5A-5B-7A-8B | V29: INTEL | W29: Ultra 5 225U | X29: Intel(R) Core(TM) Ultra 5 225U (1.50 GHz) | AD29: 32 | AE29: Intel ARC Graphics | AF29: Y | AH29: SSD-NVME | AI29: 512 | AL29: 11" | AM29: Good | AN29: PGT | AO29: IT | AP29: In used by User | AQ29: Used by Bahtiar | AU29: TRUE | AV29: =_xlfn.IFNA(INDEX(tbl_handover[No. Handover],MATCH(tbl_computer[[#This Row],[No Asset]],tbl_handover[Asset Code],0)),"")
A30: =IF(tbl_computer[[#This Row],[No Asset]]<>"",SUBTOTAL(3,INDEX(tbl_computer[No Asset],1):tbl_computer[[#This Row],[No Asset]]),"") -> 7 | B30: =IF(OR(tbl_computer[[#This Row],[Purchase Date]]="",tbl_computer[[#This Row],[Categories]]=""),"", TEXT(tbl_computer[[#This Row],[Purchase Date]],"YYMM")& _xlfn.XLOOKUP(tbl_computer[[#This Row],[Categories]],CODEX!$Z:$Z,CODEX!$W:$W,"")& TEXT(_xlfn.XLOOKUP(tbl_computer[[#This Row],[Categories]],CODEX!$Z:$Z,CODEX!$Y:$Y,""),"00")& TEXT(COUNTIFS(INDEX(tbl_computer[Purchase Date],1):tbl_computer[[#This Row],[Purchase Date]],">="&DATE(YEAR(tbl_computer[[#This Row],[Purchase Date]]),MONTH(tbl_computer[[#This Row],[Purchase Date]]),1),INDEX(tbl_computer[Purchase Date],1):tbl_computer[[#This Row],[Purchase Date]],"<"&EDATE(DATE(YEAR(tbl_computer[[#This Row],[Purchase Date]]),MONTH(tbl_computer[[#This Row],[Purchase Date]]),1),1),INDEX(tbl_computer[Categories],1):tbl_computer[[#This Row],[Categories]],tbl_computer[[#This Row],[Categories]]),"000")) -> 2601101021 | C30: 46023 | D30: PO-001 | E30: Patimban | F30: Equipment Room | G30: Computer | H30: Notebook | I30: Dell Latitude 3450 | J30: NOTEBOOK | K30: 9MHWB94 | L30: DELL | M30: Latitude 3450 | O30: PBNBEQ-SUPARNO | P30: W 11 Pro | Q30: 6HNPJ-8H7MP-47GP7-HFMG2-JB6PT | S30: N/A | T30: 28-95-29-41-CA-26 | U30: C4-D6-D3-81-63-B7 | V30: INTEL | W30: i7-1355U | X30: 13th Gen Intel(R) Core(TM) i7-1355U (1.70 GHz) | AD30: 16 | AE30: Intel ARC Graphics | AF30: Y | AH30: SSD-NVME | AI30: 512 | AL30: 11" | AM30: Good | AN30: PGT | AO30: IT | AP30: In used by User | AQ30: Used by Suparno | AU30: FALSE | AV30: =_xlfn.IFNA(INDEX(tbl_handover[No. Handover],MATCH(tbl_computer[[#This Row],[No Asset]],tbl_handover[Asset Code],0)),"")
A31: =IF(tbl_computer[[#This Row],[No Asset]]<>"",SUBTOTAL(3,INDEX(tbl_computer[No Asset],1):tbl_computer[[#This Row],[No Asset]]),"") -> 7 | B31: =IF(OR(tbl_computer[[#This Row],[Purchase Date]]="",tbl_computer[[#This Row],[Categories]]=""),"", TEXT(tbl_computer[[#This Row],[Purchase Date]],"YYMM")& _xlfn.XLOOKUP(tbl_computer[[#This Row],[Categories]],CODEX!$Z:$Z,CODEX!$W:$W,"")& TEXT(_xlfn.XLOOKUP(tbl_computer[[#This Row],[Categories]],CODEX!$Z:$Z,CODEX!$Y:$Y,""),"00")& TEXT(COUNTIFS(INDEX(tbl_computer[Purchase Date],1):tbl_computer[[#This Row],[Purchase Date]],">="&DATE(YEAR(tbl_computer[[#This Row],[Purchase Date]]),MONTH(tbl_computer[[#This Row],[Purchase Date]]),1),INDEX(tbl_computer[Purchase Date],1):tbl_computer[[#This Row],[Purchase Date]],"<"&EDATE(DATE(YEAR(tbl_computer[[#This Row],[Purchase Date]]),MONTH(tbl_computer[[#This Row],[Purchase Date]]),1),1),INDEX(tbl_computer[Categories],1):tbl_computer[[#This Row],[Categories]],tbl_computer[[#This Row],[Categories]]),"000")) -> 2601101022 | C31: 46023 | D31: PO-001 | E31: Patimban | F31: Engineer Room | G31: Computer | H31: Notebook | I31: Dell Latitude 5450 | J31: NOTEBOOK | K31: J9BLPB4 | L31: DELL | M31: Latitude 5450 | O31: PBNBIT-ITSTAFF | P31: W 11 Pro | Q31: PNKPT-WGD79-2DR6G-KXTTH-X77J6 | S31: N/A | T31: C4-0F-08-73-C0-94 | U31: C0-47-0E-47-7C-44 | V31: INTEL | W31: Ultra 5 135H | X31: Intel(R) Core(TM) Ultra 5 135H 1.70 GHz | AD31: 16 | AE31: Intel ARC Graphics | AF31: Y | AH31: SSD-NVME | AI31: 512 | AL31: 11" | AM31: Good | AN31: PSI | AO31: IT | AP31: In used by User | AQ31: Used by IT Staff; Ex. Dedy Saputra | AU31: TRUE | AV31: =_xlfn.IFNA(INDEX(tbl_handover[No. Handover],MATCH(tbl_computer[[#This Row],[No Asset]],tbl_handover[Asset Code],0)),"")
A32: =IF(tbl_computer[[#This Row],[No Asset]]<>"",SUBTOTAL(3,INDEX(tbl_computer[No Asset],1):tbl_computer[[#This Row],[No Asset]]),"") -> 7 | B32: =IF(OR(tbl_computer[[#This Row],[Purchase Date]]="",tbl_computer[[#This Row],[Categories]]=""),"", TEXT(tbl_computer[[#This Row],[Purchase Date]],"YYMM")& _xlfn.XLOOKUP(tbl_computer[[#This Row],[Categories]],CODEX!$Z:$Z,CODEX!$W:$W,"")& TEXT(_xlfn.XLOOKUP(tbl_computer[[#This Row],[Categories]],CODEX!$Z:$Z,CODEX!$Y:$Y,""),"00")& TEXT(COUNTIFS(INDEX(tbl_computer[Purchase Date],1):tbl_computer[[#This Row],[Purchase Date]],">="&DATE(YEAR(tbl_computer[[#This Row],[Purchase Date]]),MONTH(tbl_computer[[#This Row],[Purchase Date]]),1),INDEX(tbl_computer[Purchase Date],1):tbl_computer[[#This Row],[Purchase Date]],"<"&EDATE(DATE(YEAR(tbl_computer[[#This Row],[Purchase Date]]),MONTH(tbl_computer[[#This Row],[Purchase Date]]),1),1),INDEX(tbl_computer[Categories],1):tbl_computer[[#This Row],[Categories]],tbl_computer[[#This Row],[Categories]]),"000")) -> 2601101023 | C32: 46023 | D32: PO-001 | E32: Patimban | F32: Customs Gate-In | G32: Computer | H32: PC | I32: HP Pro Mini PC 400 G9 | J32: MFF PC | K32: 8CC6090X4Z | L32: HP | M32: Pro Mini PC 400 G9 | O32: PBPCHS-GATEIN | P32: W 11 Pro | S32: N/A | T32: EC-3A-56-78-1A-A6 | U32: B4-E2-5B-77-5C-9C | V32: INTEL | W32: i7-14700T | X32: Intel(R) Core(TM) i7-14700T (1.30 GHz) | AD32: 16 | AE32: UHD Graphics 770 | AF32: Y | AH32: SSD-NVME | AI32: 1024 | AL32: 27" | AM32: Lost | AN32: PGT | AO32: IT | AP32: Idle | AQ32: Lost mini-PC in Customs Gate-In | AU32: FALSE | AV32: =_xlfn.IFNA(INDEX(tbl_handover[No. Handover],MATCH(tbl_computer[[#This Row],[No Asset]],tbl_handover[Asset Code],0)),"")
A33: =IF(tbl_computer[[#This Row],[No Asset]]<>"",SUBTOTAL(3,INDEX(tbl_computer[No Asset],1):tbl_computer[[#This Row],[No Asset]]),"") -> 7 | B33: =IF(OR(tbl_computer[[#This Row],[Purchase Date]]="",tbl_computer[[#This Row],[Categories]]=""),"", TEXT(tbl_computer[[#This Row],[Purchase Date]],"YYMM")& _xlfn.XLOOKUP(tbl_computer[[#This Row],[Categories]],CODEX!$Z:$Z,CODEX!$W:$W,"")& TEXT(_xlfn.XLOOKUP(tbl_computer[[#This Row],[Categories]],CODEX!$Z:$Z,CODEX!$Y:$Y,""),"00")& TEXT(COUNTIFS(INDEX(tbl_computer[Purchase Date],1):tbl_computer[[#This Row],[Purchase Date]],">="&DATE(YEAR(tbl_computer[[#This Row],[Purchase Date]]),MONTH(tbl_computer[[#This Row],[Purchase Date]]),1),INDEX(tbl_computer[Purchase Date],1):tbl_computer[[#This Row],[Purchase Date]],"<"&EDATE(DATE(YEAR(tbl_computer[[#This Row],[Purchase Date]]),MONTH(tbl_computer[[#This Row],[Purchase Date]]),1),1),INDEX(tbl_computer[Categories],1):tbl_computer[[#This Row],[Categories]],tbl_computer[[#This Row],[Categories]]),"000")) -> 2601101024 | C33: 46023 | D33: PO-001 | E33: Patimban | F33: Engineer Room | G33: Computer | H33: PC | I33: HP Pro Mini PC 400 G9 | J33: MFF PC | K33: 8CC6090X52 | L33: HP | M33: Pro Mini PC 400 G9 | O33: PBPCIT-SPARE | P33: W 11 Pro | Q33: KBPJ3-NQXCH-98TJR-VFC3Q-63B6G | R33: 10.90.10.18 | S33: N/A | T33: EC-3A-56-78-1B-F0 | U33: 00-09-0F-FE-00-01 | V33: INTEL | W33: i7-14700T | X33: Intel(R) Core(TM) i7-14700T (1.30 GHz) | AD33: 16 | AE33: UHD Graphics 770 | AF33: Y | AH33: SSD-NVME | AI33: 1024 | AL33: 27" | AM33: Good | AN33: PGT | AO33: IT | AP33: In used by User | AQ33: Exchange from PBPCHS-GATEOUT; Used by IT Staff | AU33: TRUE | AV33: =_xlfn.IFNA(INDEX(tbl_handover[No. Handover],MATCH(tbl_computer[[#This Row],[No Asset]],tbl_handover[Asset Code],0)),"")
